<?xml version="1.0" encoding="utf-8"?>
<!-- This URDF was automatically created by SolidWorks to URDF Exporter! Originally created by Stephen Brawner (brawner@gmail.com) 
     Commit Version: 1.6.0-1-g15f4949  Build Version: 1.6.7594.29634
     For more information, please see http://wiki.ros.org/sw_urdf_exporter -->
<robot
  name="robot_siad7n">
  <link
    name="base_link">
    <inertial>
      <origin
        xyz="-0.000142781203599816 0.0532705876648457 0.0677974979176462"
        rpy="0 0 0" />
      <mass
        value="9.56045935245332" />
      <inertia
        ixx="0.106984452971487"
        ixy="0.000141321543711577"
        ixz="7.32310895103946E-05"
        iyy="0.0622135700565055"
        iyz="-0.0105783354798607"
        izz="0.136512878649761" />
    </inertial>
    <visual>
      <origin
        xyz="0 0 0"
        rpy="0 0 0" />
      <geometry>
        <mesh
          filename="package://robot_siad7n/meshes/base_link.STL" />
      </geometry>
      <material
        name="">
        <color
          rgba="0.23921568627451 0.474509803921569 0.133333333333333 1" />
      </material>
    </visual>
    <collision>
      <origin
        xyz="0 0 0"
        rpy="0 0 0" />
      <geometry>
        <mesh
          filename="package://robot_siad7n/meshes/base_link.STL" />
      </geometry>
    </collision>
  </link>
  <link
    name="link_1">
    <inertial>
      <origin
        xyz="1.00333108653757E-06 0.189106618676997 -0.0156119231451303"
        rpy="0 0 0" />
      <mass
        value="0.0117569497463645" />
      <inertia
        ixx="0.000183154145712612"
        ixy="-1.40452305503904E-09"
        ixz="5.87350460962656E-10"
        iyy="6.17033488863618E-05"
        iyz="1.36703017961243E-05"
        izz="0.000186679492541189" />
    </inertial>
    <visual>
      <origin
        xyz="0 0 0"
        rpy="0 0 0" />
      <geometry>
        <mesh
          filename="package://robot_siad7n/meshes/link_1.STL" />
      </geometry>
      <material
        name="">
        <color
          rgba="0.23921568627451 0.474509803921569 0.129411764705882 1" />
      </material>
    </visual>
    <collision>
      <origin
        xyz="0 0 0"
        rpy="0 0 0" />
      <geometry>
        <mesh
          filename="package://robot_siad7n/meshes/link_1.STL" />
      </geometry>
    </collision>
  </link>
  <joint
    name="joint_1"
    type="revolute">
    <origin
      xyz="0 0 0.1175"
      rpy="1.5708 0 0" />
    <parent
      link="base_link" />
    <child
      link="link_1" />
    <axis
      xyz="0 1 0" />
    <limit
      lower="-1.5708"
      upper="1.5708"
      effort="100"
      velocity="50" />
  </joint>
  <link
    name="link_2">
    <inertial>
      <origin
        xyz="9.94785703299712E-06 0.27268310679977 0.0295582992008025"
        rpy="0 0 0" />
      <mass
        value="10.0552877935744" />
      <inertia
        ixx="0.338020265619112"
        ixy="-1.29257105019896E-05"
        ixz="2.92886810346626E-06"
        iyy="0.0467291504250425"
        iyz="0.0229500840245969"
        izz="0.339753837370959" />
    </inertial>
    <visual>
      <origin
        xyz="0 0 0"
        rpy="0 0 0" />
      <geometry>
        <mesh
          filename="package://robot_siad7n/meshes/link_2.STL" />
      </geometry>
      <material
        name="">
        <color
          rgba="0.792156862745098 0.819607843137255 0.933333333333333 1" />
      </material>
    </visual>
    <collision>
      <origin
        xyz="0 0 0"
        rpy="0 0 0" />
      <geometry>
        <mesh
          filename="package://robot_siad7n/meshes/link_2.STL" />
      </geometry>
    </collision>
  </link>
  <joint
    name="joint_2"
    type="revolute">
    <origin
      xyz="0 0.298 0"
      rpy="0 0 0" />
    <parent
      link="link_1" />
    <child
      link="link_2" />
    <axis
      xyz="0 0 1" />
    <limit
      lower="-1.5708"
      upper="1.5708"
      effort="0"
      velocity="0" />
  </joint>
  <link
    name="link_3">
    <inertial>
      <origin
        xyz="9.53265518154114E-06 -0.153702036545705 -0.133410762424367"
        rpy="0 0 0" />
      <mass
        value="0.00843890832225914" />
      <inertia
        ixx="0.000117451151873452"
        ixy="1.10991298245416E-09"
        ixz="-4.98586112813587E-09"
        iyy="7.00119097755916E-05"
        iyz="3.60892225982952E-05"
        izz="8.17537404382889E-05" />
    </inertial>
    <visual>
      <origin
        xyz="0 0 0"
        rpy="0 0 0" />
      <geometry>
        <mesh
          filename="package://robot_siad7n/meshes/link_3.STL" />
      </geometry>
      <material
        name="">
        <color
          rgba="0.745098039215686 0.745098039215686 0.745098039215686 1" />
      </material>
    </visual>
    <collision>
      <origin
        xyz="0 0 0"
        rpy="0 0 0" />
      <geometry>
        <mesh
          filename="package://robot_siad7n/meshes/link_3.STL" />
      </geometry>
    </collision>
  </link>
  <joint
    name="joint_3"
    type="prismatic">
    <origin
      xyz="3.4347E-05 0.3019 0.265"
      rpy="0 0 3.1416" />
    <parent
      link="link_2" />
    <child
      link="link_3" />
    <axis
      xyz="0 1 0" />
    <limit
      lower="-0.32"
      upper="0"
      effort="100"
      velocity="10" />
  </joint>
  <link
    name="link_4">
    <inertial>
      <origin
        xyz="-7.30288412409408E-07 0.209780950057377 -0.0209890962252118"
        rpy="0 0 0" />
      <mass
        value="6.45548612950254" />
      <inertia
        ixx="0.110031218238487"
        ixy="-8.21723912250207E-06"
        ixz="-1.43282615572879E-06"
        iyy="0.0163209157770267"
        iyz="-0.00683093275863895"
        izz="0.111596153155119" />
    </inertial>
    <visual>
      <origin
        xyz="0 0 0"
        rpy="0 0 0" />
      <geometry>
        <mesh
          filename="package://robot_siad7n/meshes/link_4.STL" />
      </geometry>
      <material
        name="">
        <color
          rgba="0.792156862745098 0.819607843137255 0.933333333333333 1" />
      </material>
    </visual>
    <collision>
      <origin
        xyz="0 0 0"
        rpy="0 0 0" />
      <geometry>
        <mesh
          filename="package://robot_siad7n/meshes/link_4.STL" />
      </geometry>
    </collision>
  </link>
  <joint
    name="joint_4"
    type="revolute">
    <origin
      xyz="0 -0.2426 0"
      rpy="-3.1416 0 -1.5708" />
    <parent
      link="link_3" />
    <child
      link="link_4" />
    <axis
      xyz="0 0 1" />
    <limit
      lower="-4.5379"
      upper="1.3963"
      effort="0"
      velocity="0" />
  </joint>
  <link
    name="link_5">
    <inertial>
      <origin
        xyz="0.000129398977391504 0.117453332073031 0.0765460795634565"
        rpy="0 0 0" />
      <mass
        value="0.00287980676910192" />
      <inertia
        ixx="2.18028328273116E-05"
        ixy="2.53211631323968E-08"
        ixz="-2.18654277813101E-08"
        iyy="1.07070235010784E-05"
        iyz="6.40548744505837E-06"
        izz="1.8114766863912E-05" />
    </inertial>
    <visual>
      <origin
        xyz="0 0 0"
        rpy="0 0 0" />
      <geometry>
        <mesh
          filename="package://robot_siad7n/meshes/link_5.STL" />
      </geometry>
      <material
        name="">
        <color
          rgba="0.745098039215686 0.745098039215686 0.745098039215686 1" />
      </material>
    </visual>
    <collision>
      <origin
        xyz="0 0 0"
        rpy="0 0 0" />
      <geometry>
        <mesh
          filename="package://robot_siad7n/meshes/link_5.STL" />
      </geometry>
    </collision>
  </link>
  <joint
    name="joint_5"
    type="prismatic">
    <origin
      xyz="0.160499999999997 0.306999974999982 0.000853052852609892"
      rpy="0 -1.5707963267949 0" />
    <parent
      link="link_4" />
    <child
      link="link_5" />
    <axis
      xyz="0 1 0" />
    <limit
      lower="0"
      upper="0.25"
      effort="0"
      velocity="0" />
  </joint>
  <link
    name="link_6">
    <inertial>
      <origin
        xyz="9.82919591735465E-06 0.0698495333218837 0.00199805459234836"
        rpy="0 0 0" />
      <mass
        value="0.00201842025658046" />
      <inertia
        ixx="9.76013914138224E-06"
        ixy="-1.90464270060181E-09"
        ixz="2.8245595760541E-10"
        iyy="4.29998931193969E-06"
        iyz="2.15922124437545E-06"
        izz="9.77941249617458E-06" />
    </inertial>
    <visual>
      <origin
        xyz="0 0 0"
        rpy="0 0 0" />
      <geometry>
        <mesh
          filename="package://robot_siad7n/meshes/link_6.STL" />
      </geometry>
      <material
        name="">
        <color
          rgba="0.23921568627451 0.474509803921569 0.129411764705882 1" />
      </material>
    </visual>
    <collision>
      <origin
        xyz="0 0 0"
        rpy="0 0 0" />
      <geometry>
        <mesh
          filename="package://robot_siad7n/meshes/link_6.STL" />
      </geometry>
    </collision>
  </link>
  <joint
    name="joint_6"
    type="revolute">
    <origin
      xyz="0 0.181000025000001 0"
      rpy="3.14159265358979 0 3.14159265358979" />
    <parent
      link="link_5" />
    <child
      link="link_6" />
    <axis
      xyz="0 0 1" />
    <limit
      lower="-1.5708"
      upper="1.5708"
      effort="0"
      velocity="0" />
  </joint>
  <link
    name="EF">
    <inertial>
      <origin
        xyz="-0.00019051739774667 0.00862752234674491 -2.4749311783534E-05"
        rpy="0 0 0" />
      <mass
        value="9.59762719689292E-05" />
      <inertia
        ixx="5.9834661308121E-08"
        ixy="2.02236286461034E-11"
        ixz="-5.68210062676186E-10"
        iyy="1.15195799642585E-07"
        iyz="1.77104498784613E-12"
        izz="5.84840093540985E-08" />
    </inertial>
    <visual>
      <origin
        xyz="0 0 0"
        rpy="0 0 0" />
      <geometry>
        <mesh
          filename="package://robot_siad7n/meshes/EF.STL" />
      </geometry>
      <material
        name="">
        <color
          rgba="0.23921568627451 0.474509803921569 0.129411764705882 1" />
      </material>
    </visual>
    <collision>
      <origin
        xyz="0 0 0"
        rpy="0 0 0" />
      <geometry>
        <mesh
          filename="package://robot_siad7n/meshes/EF.STL" />
      </geometry>
    </collision>
  </link>
  <joint
    name="joint_7"
    type="revolute">
    <origin
      xyz="0 0.162188781523228 -0.0160000000000009"
      rpy="3.14159265358979 0 3.14159265358979" />
    <parent
      link="link_6" />
    <child
      link="EF" />
    <axis
      xyz="0 1 0" />
    <limit
      lower="-3.1416"
      upper="3.1416"
      effort="0"
      velocity="0" />
  </joint>
</robot>