<?xml version="1.0" encoding="utf-8"?>
<!-- This URDF was automatically created by SolidWorks to URDF Exporter! Originally created by Stephen Brawner (brawner@gmail.com) 
     Commit Version: 1.6.0-1-g15f4949  Build Version: 1.6.7594.29634
     For more information, please see http://wiki.ros.org/sw_urdf_exporter -->
<robot
  name="robot_siad7n">
  <link
    name="base_link">
    <inertial>
      <origin
        xyz="-0.00014278 0.053271 0.067797"
        rpy="0 0 0" />
      <mass
        value="9.5605" />
      <inertia
        ixx="0.10698"
        ixy="0.00014132"
        ixz="7.3231E-05"
        iyy="0.062214"
        iyz="-0.010578"
        izz="0.13651" />
    </inertial>
    <visual>
      <origin
        xyz="0 0 0"
        rpy="0 0 0" />
      <geometry>
        <mesh
          filename="package://robot_siad7n/meshes/base_link.STL" />
      </geometry>
      <material
        name="">
        <color
          rgba="0.23922 0.47451 0.13333 1" />
      </material>
    </visual>
    <collision>
      <origin
        xyz="0 0 0"
        rpy="0 0 0" />
      <geometry>
        <mesh
          filename="package://robot_siad7n/meshes/base_link.STL" />
      </geometry>
    </collision>
  </link>
  <link
    name="link_1">
    <inertial>
      <origin
        xyz="1.00333110064812E-06 0.189106618677028 -0.0156119231452269"
        rpy="0 0 0" />
      <mass
        value="0.0117569497463589" />
      <inertia
        ixx="0.000183154145712548"
        ixy="-1.40452306098155E-09"
        ixz="5.87350401589273E-10"
        iyy="6.17033488863356E-05"
        iyz="1.36703017960949E-05"
        izz="0.000186679492541156" />
    </inertial>
    <visual>
      <origin
        xyz="0 0 0"
        rpy="0 0 0" />
      <geometry>
        <mesh
          filename="package://robot_siad7n/meshes/link_1.STL" />
      </geometry>
      <material
        name="">
        <color
          rgba="0.23921568627451 0.474509803921569 0.129411764705882 1" />
      </material>
    </visual>
    <collision>
      <origin
        xyz="0 0 0"
        rpy="0 0 0" />
      <geometry>
        <mesh
          filename="package://robot_siad7n/meshes/link_1.STL" />
      </geometry>
    </collision>
  </link>
  <joint
    name="joint_1"
    type="revolute">
    <origin
      xyz="0 0 0.1175"
      rpy="1.5708 0 0" />
    <parent
      link="base_link" />
    <child
      link="link_1" />
    <axis
      xyz="0 1 0" />
    <limit
      lower="-1.5708"
      upper="1.5708"
      effort="100"
      velocity="50" />
  </joint>
  <link
    name="link_2">
    <inertial>
      <origin
        xyz="9.94785699382701E-06 0.272683106799616 0.0295582992008662"
        rpy="0 0 0" />
      <mass
        value="10.0552877935848" />
      <inertia
        ixx="0.338020265619125"
        ixy="-1.29257104925891E-05"
        ixz="2.92886813292044E-06"
        iyy="0.0467291504250512"
        iyz="0.0229500840245831"
        izz="0.339753837370967" />
    </inertial>
    <visual>
      <origin
        xyz="0 0 0"
        rpy="0 0 0" />
      <geometry>
        <mesh
          filename="package://robot_siad7n/meshes/link_2.STL" />
      </geometry>
      <material
        name="">
        <color
          rgba="0.792156862745098 0.819607843137255 0.933333333333333 1" />
      </material>
    </visual>
    <collision>
      <origin
        xyz="0 0 0"
        rpy="0 0 0" />
      <geometry>
        <mesh
          filename="package://robot_siad7n/meshes/link_2.STL" />
      </geometry>
    </collision>
  </link>
  <joint
    name="joint_2"
    type="revolute">
    <origin
      xyz="0 0.298 0"
      rpy="0 0 0" />
    <parent
      link="link_1" />
    <child
      link="link_2" />
    <axis
      xyz="0 0 1" />
    <limit
      lower="-1.5708"
      upper="1.5708"
      effort="0"
      velocity="0" />
  </joint>
  <link
    name="link_3">
    <inertial>
      <origin
        xyz="9.53265518652332E-06 -0.153702036545708 -0.133410762424367"
        rpy="0 0 0" />
      <mass
        value="0.00843890832225914" />
      <inertia
        ixx="0.000117451151873452"
        ixy="1.1099129828021E-09"
        ixz="-4.98586112838079E-09"
        iyy="7.00119097755915E-05"
        iyz="3.60892225982952E-05"
        izz="8.17537404382889E-05" />
    </inertial>
    <visual>
      <origin
        xyz="0 0 0"
        rpy="0 0 0" />
      <geometry>
        <mesh
          filename="package://robot_siad7n/meshes/link_3.STL" />
      </geometry>
      <material
        name="">
        <color
          rgba="0.745098039215686 0.745098039215686 0.745098039215686 1" />
      </material>
    </visual>
    <collision>
      <origin
        xyz="0 0 0"
        rpy="0 0 0" />
      <geometry>
        <mesh
          filename="package://robot_siad7n/meshes/link_3.STL" />
      </geometry>
    </collision>
  </link>
  <joint
    name="join_3"
    type="prismatic">
    <origin
      xyz="3.4347E-05 0.3019 0.265"
      rpy="0 0 3.1416" />
    <parent
      link="link_2" />
    <child
      link="link_3" />
    <axis
      xyz="0 1 0" />
    <limit
      lower="0"
      upper="0.32"
      effort="100"
      velocity="10" />
  </joint>
  <link
    name="link_4">
    <inertial>
      <origin
        xyz="-7.29962949086449E-07 0.209780950560694 -0.0209890962299917"
        rpy="0 0 0" />
      <mass
        value="6.45548607858182" />
      <inertia
        ixx="0.110031218041107"
        ixy="-8.21737617566412E-06"
        ixz="-1.43284795299844E-06"
        iyy="0.0163209156851634"
        iyz="-0.0068309327202393"
        izz="0.111596152864531" />
    </inertial>
    <visual>
      <origin
        xyz="0 0 0"
        rpy="0 0 0" />
      <geometry>
        <mesh
          filename="package://robot_siad7n/meshes/link_4.STL" />
      </geometry>
      <material
        name="">
        <color
          rgba="0.792156862745098 0.819607843137255 0.933333333333333 1" />
      </material>
    </visual>
    <collision>
      <origin
        xyz="0 0 0"
        rpy="0 0 0" />
      <geometry>
        <mesh
          filename="package://robot_siad7n/meshes/link_4.STL" />
      </geometry>
    </collision>
  </link>
  <joint
    name="joint_4"
    type="revolute">
    <origin
      xyz="0 -0.2426 0"
      rpy="3.1416 0 -1.5708" />
    <parent
      link="link_3" />
    <child
      link="link_4" />
    <axis
      xyz="0 0 1" />
    <limit
      lower="-1.3963"
      upper="4.5379"
      effort="0"
      velocity="0" />
  </joint>
  <link
    name="link_5">
    <inertial>
      <origin
        xyz="0.000129398977390949 0.117453332073065 0.0765460795634614"
        rpy="0 0 0" />
      <mass
        value="0.00287980676910192" />
      <inertia
        ixx="2.18028328273116E-05"
        ixy="2.53211631323927E-08"
        ixz="-2.18654277813073E-08"
        iyy="1.07070235010784E-05"
        iyz="6.40548744505838E-06"
        izz="1.81147668639118E-05" />
    </inertial>
    <visual>
      <origin
        xyz="0 0 0"
        rpy="0 0 0" />
      <geometry>
        <mesh
          filename="package://robot_siad7n/meshes/link_5.STL" />
      </geometry>
      <material
        name="">
        <color
          rgba="0.745098039215686 0.745098039215686 0.745098039215686 1" />
      </material>
    </visual>
    <collision>
      <origin
        xyz="0 0 0"
        rpy="0 0 0" />
      <geometry>
        <mesh
          filename="package://robot_siad7n/meshes/link_5.STL" />
      </geometry>
    </collision>
  </link>
  <joint
    name="joint_5"
    type="prismatic">
    <origin
      xyz="0.1605 0.307 0.00085305"
      rpy="3.1416 -1.5708 0" />
    <parent
      link="link_4" />
    <child
      link="link_5" />
    <axis
      xyz="0 1 0" />
    <limit
      lower="0"
      upper="0.25"
      effort="0"
      velocity="0" />
  </joint>
  <link
    name="link_6">
    <inertial>
      <origin
        xyz="9.8292E-06 0.06985 0.0019981"
        rpy="0 0 0" />
      <mass
        value="0.0020184" />
      <inertia
        ixx="9.7601E-06"
        ixy="-1.9046E-09"
        ixz="2.8245E-10"
        iyy="4.3E-06"
        iyz="2.1592E-06"
        izz="9.7794E-06" />
    </inertial>
    <visual>
      <origin
        xyz="0 0 0"
        rpy="0 0 0" />
      <geometry>
        <mesh
          filename="package://robot_siad7n/meshes/link_6.STL" />
      </geometry>
      <material
        name="">
        <color
          rgba="0.23922 0.47451 0.12941 1" />
      </material>
    </visual>
    <collision>
      <origin
        xyz="0 0 0"
        rpy="0 0 0" />
      <geometry>
        <mesh
          filename="package://robot_siad7n/meshes/link_6.STL" />
      </geometry>
    </collision>
  </link>
  <joint
    name="joint_6"
    type="revolute">
    <origin
      xyz="0 0.181 0"
      rpy="3.1416 0 3.1416" />
    <parent
      link="link_5" />
    <child
      link="link_6" />
    <axis
      xyz="0 0 1" />
    <limit
      lower="-1.5708"
      upper="1.5708"
      effort="0"
      velocity="0" />
  </joint>
  <link
    name="EF">
    <inertial>
      <origin
        xyz="-0.000190517397762102 0.00862752234673336 -2.47493117773168E-05"
        rpy="0 0 0" />
      <mass
        value="9.59762719689291E-05" />
      <inertia
        ixx="5.98346613081207E-08"
        ixy="2.02236286460032E-11"
        ixz="-5.68210062676005E-10"
        iyy="1.15195799642585E-07"
        iyz="1.77104498741018E-12"
        izz="5.84840093540987E-08" />
    </inertial>
    <visual>
      <origin
        xyz="0 0 0"
        rpy="0 0 0" />
      <geometry>
        <mesh
          filename="package://robot_siad7n/meshes/EF.STL" />
      </geometry>
      <material
        name="">
        <color
          rgba="0.23921568627451 0.474509803921569 0.129411764705882 1" />
      </material>
    </visual>
    <collision>
      <origin
        xyz="0 0 0"
        rpy="0 0 0" />
      <geometry>
        <mesh
          filename="package://robot_siad7n/meshes/EF.STL" />
      </geometry>
    </collision>
  </link>
  <joint
    name="joint_7"
    type="revolute">
    <origin
      xyz="0 0.16219 -0.016"
      rpy="3.1416 -1.5708 0" />
    <parent
      link="link_6" />
    <child
      link="EF" />
    <axis
      xyz="0 1 0" />
    <limit
      lower="-3.1416"
      upper="3.1416"
      effort="0"
      velocity="0" />
  </joint>
</robot>