<?xml version="1.0" encoding="utf-8"?>
<!-- This URDF was automatically created by SolidWorks to URDF Exporter! Originally created by Stephen Brawner (brawner@gmail.com) 
     Commit Version: 1.6.0-1-g15f4949  Build Version: 1.6.7594.29634
     For more information, please see http://wiki.ros.org/sw_urdf_exporter -->
<robot
  name="robot_siad7n">
  <link
    name="base_link">
    <inertial>
      <origin
        xyz="-0.053271 -0.00014278 0.067797"
        rpy="0 0 0" />
      <mass
        value="9.5605" />
      <inertia
        ixx="0.062214"
        ixy="-0.00014132"
        ixz="0.010578"
        iyy="0.10698"
        iyz="7.3231E-05"
        izz="0.13651" />
    </inertial>
    <visual>
      <origin
        xyz="0 0 0"
        rpy="0 0 0" />
      <geometry>
        <mesh
          filename="package://robot_siad7n/meshes/base_link.STL" />
      </geometry>
      <material
        name="">
        <color
          rgba="0.23922 0.47451 0.13333 1" />
      </material>
    </visual>
    <collision>
      <origin
        xyz="0 0 0"
        rpy="0 0 0" />
      <geometry>
        <mesh
          filename="package://robot_siad7n/meshes/base_link.STL" />
      </geometry>
    </collision>
  </link>
  <link
    name="link_1">
    <inertial>
      <origin
        xyz="1.0033E-06 0.18911 -0.015612"
        rpy="0 0 0" />
      <mass
        value="0.011757" />
      <inertia
        ixx="0.00018315"
        ixy="-1.4045E-09"
        ixz="5.8735E-10"
        iyy="6.1703E-05"
        iyz="1.367E-05"
        izz="0.00018668" />
    </inertial>
    <visual>
      <origin
        xyz="0 0 0"
        rpy="0 0 0" />
      <geometry>
        <mesh
          filename="package://robot_siad7n/meshes/link_1.STL" />
      </geometry>
      <material
        name="">
        <color
          rgba="0.23922 0.47451 0.12941 1" />
      </material>
    </visual>
    <collision>
      <origin
        xyz="0 0 0"
        rpy="0 0 0" />
      <geometry>
        <mesh
          filename="package://robot_siad7n/meshes/link_1.STL" />
      </geometry>
    </collision>
  </link>
  <joint
    name="joint_1"
    type="revolute">
    <origin
      xyz="0 0 0.1175"
      rpy="1.5708 0 1.5708" />
    <parent
      link="base_link" />
    <child
      link="link_1" />
    <axis
      xyz="0 1 0" />
    <limit
      lower="-1.5708"
      upper="1.5708"
      effort="100"
      velocity="50" />
  </joint>
  <link
    name="link_2">
    <inertial>
      <origin
        xyz="9.9479E-06 0.27268 0.029558"
        rpy="0 0 0" />
      <mass
        value="10.055" />
      <inertia
        ixx="0.33802"
        ixy="-1.2926E-05"
        ixz="2.9289E-06"
        iyy="0.046729"
        iyz="0.02295"
        izz="0.33975" />
    </inertial>
    <visual>
      <origin
        xyz="0 0 0"
        rpy="0 0 0" />
      <geometry>
        <mesh
          filename="package://robot_siad7n/meshes/link_2.STL" />
      </geometry>
      <material
        name="">
        <color
          rgba="0.79216 0.81961 0.93333 1" />
      </material>
    </visual>
    <collision>
      <origin
        xyz="0 0 0"
        rpy="0 0 0" />
      <geometry>
        <mesh
          filename="package://robot_siad7n/meshes/link_2.STL" />
      </geometry>
    </collision>
  </link>
  <joint
    name="joint_2"
    type="revolute">
    <origin
      xyz="0 0.298 0"
      rpy="0 0 0" />
    <parent
      link="link_1" />
    <child
      link="link_2" />
    <axis
      xyz="0 0 1" />
    <limit
      lower="-1.5708"
      upper="1.5708"
      effort="0"
      velocity="0" />
  </joint>
  <link
    name="link_3">
    <inertial>
      <origin
        xyz="9.53265518154118E-06 -0.153702036545705 -0.133410762424367"
        rpy="0 0 0" />
      <mass
        value="0.00843890832225914" />
      <inertia
        ixx="0.000117451151873452"
        ixy="1.10991298245416E-09"
        ixz="-4.98586112813587E-09"
        iyy="7.00119097755916E-05"
        iyz="3.60892225982952E-05"
        izz="8.17537404382889E-05" />
    </inertial>
    <visual>
      <origin
        xyz="0 0 0"
        rpy="0 0 0" />
      <geometry>
        <mesh
          filename="package://robot_siad7n/meshes/link_3.STL" />
      </geometry>
      <material
        name="">
        <color
          rgba="0.745098039215686 0.745098039215686 0.745098039215686 1" />
      </material>
    </visual>
    <collision>
      <origin
        xyz="0 0 0"
        rpy="0 0 0" />
      <geometry>
        <mesh
          filename="package://robot_siad7n/meshes/link_3.STL" />
      </geometry>
    </collision>
  </link>
  <joint
    name="joint_3"
    type="prismatic">
    <origin
      xyz="3.43471413583333E-05 0.301899975 0.265"
      rpy="0 0 3.14159265358979" />
    <parent
      link="link_2" />
    <child
      link="link_3" />
    <axis
      xyz="0 1 0" />
    <limit
      lower="0"
      upper="0.32"
      effort="100"
      velocity="10" />
  </joint>
  <link
    name="link_4">
    <inertial>
      <origin
        xyz="-7.3028841252043E-07 0.209780950057377 -0.0209890962252118"
        rpy="0 0 0" />
      <mass
        value="6.45548612950254" />
      <inertia
        ixx="0.110031218238487"
        ixy="-8.21723912250209E-06"
        ixz="-1.43282615572878E-06"
        iyy="0.0163209157770267"
        iyz="-0.00683093275863895"
        izz="0.111596153155119" />
    </inertial>
    <visual>
      <origin
        xyz="0 0 0"
        rpy="0 0 0" />
      <geometry>
        <mesh
          filename="package://robot_siad7n/meshes/link_4.STL" />
      </geometry>
      <material
        name="">
        <color
          rgba="0.792156862745098 0.819607843137255 0.933333333333333 1" />
      </material>
    </visual>
    <collision>
      <origin
        xyz="0 0 0"
        rpy="0 0 0" />
      <geometry>
        <mesh
          filename="package://robot_siad7n/meshes/link_4.STL" />
      </geometry>
    </collision>
  </link>
  <joint
    name="joint_4"
    type="revolute">
    <origin
      xyz="0 -0.242600025 0"
      rpy="-3.14159265358979 0 -1.5707963267949" />
    <parent
      link="link_3" />
    <child
      link="link_4" />
    <axis
      xyz="0 0 1" />
    <limit
      lower="-4.5379"
      upper="1.3963"
      effort="0"
      velocity="0" />
  </joint>
  <link
    name="link_5">
    <inertial>
      <origin
        xyz="0.0001294 0.11745 0.076546"
        rpy="0 0 0" />
      <mass
        value="0.0028798" />
      <inertia
        ixx="2.1803E-05"
        ixy="2.5321E-08"
        ixz="-2.1865E-08"
        iyy="1.0707E-05"
        iyz="6.4055E-06"
        izz="1.8115E-05" />
    </inertial>
    <visual>
      <origin
        xyz="0 0 0"
        rpy="0 0 0" />
      <geometry>
        <mesh
          filename="package://robot_siad7n/meshes/link_5.STL" />
      </geometry>
      <material
        name="">
        <color
          rgba="0.7451 0.7451 0.7451 1" />
      </material>
    </visual>
    <collision>
      <origin
        xyz="0 0 0"
        rpy="0 0 0" />
      <geometry>
        <mesh
          filename="package://robot_siad7n/meshes/link_5.STL" />
      </geometry>
    </collision>
  </link>
  <joint
    name="joint_5"
    type="prismatic">
    <origin
      xyz="0.160499999999997 0.306999974999982 0.000853052852609892"
      rpy="3.14159265358979 -1.5707963267949 0" />
    <parent
      link="link_4" />
    <child
      link="link_5" />
    <axis
      xyz="0 1 0" />
    <limit
      lower="0"
      upper="0.25"
      effort="0"
      velocity="0" />
  </joint>
  <link
    name="link_6">
    <inertial>
      <origin
        xyz="9.8292E-06 0.06985 0.0019981"
        rpy="0 0 0" />
      <mass
        value="0.0020184" />
      <inertia
        ixx="9.7601E-06"
        ixy="-1.9046E-09"
        ixz="2.8246E-10"
        iyy="4.3E-06"
        iyz="2.1592E-06"
        izz="9.7794E-06" />
    </inertial>
    <visual>
      <origin
        xyz="0 0 0"
        rpy="0 0 0" />
      <geometry>
        <mesh
          filename="package://robot_siad7n/meshes/link_6.STL" />
      </geometry>
      <material
        name="">
        <color
          rgba="0.23922 0.47451 0.12941 1" />
      </material>
    </visual>
    <collision>
      <origin
        xyz="0 0 0"
        rpy="0 0 0" />
      <geometry>
        <mesh
          filename="package://robot_siad7n/meshes/link_6.STL" />
      </geometry>
    </collision>
  </link>
  <joint
    name="joint_6"
    type="revolute">
    <origin
      xyz="0 0.181000025000001 0"
      rpy="3.14159265358979 0 3.14159265358979" />
    <parent
      link="link_5" />
    <child
      link="link_6" />
    <axis
      xyz="0 0 1" />
    <limit
      lower="-1.5708"
      upper="1.5708"
      effort="0"
      velocity="0" />
  </joint>
  <link
    name="EF">
    <inertial>
      <origin
        xyz="-0.00019052 0.0086275 -2.4749E-05"
        rpy="0 0 0" />
      <mass
        value="9.5976E-05" />
      <inertia
        ixx="5.9835E-08"
        ixy="2.0224E-11"
        ixz="-5.6821E-10"
        iyy="1.152E-07"
        iyz="1.771E-12"
        izz="5.8484E-08" />
    </inertial>
    <visual>
      <origin
        xyz="0 0 0"
        rpy="0 0 0" />
      <geometry>
        <mesh
          filename="package://robot_siad7n/meshes/EF.STL" />
      </geometry>
      <material
        name="">
        <color
          rgba="0.23922 0.47451 0.12941 1" />
      </material>
    </visual>
    <collision>
      <origin
        xyz="0 0 0"
        rpy="0 0 0" />
      <geometry>
        <mesh
          filename="package://robot_siad7n/meshes/EF.STL" />
      </geometry>
    </collision>
  </link>
  <joint
    name="joint_7"
    type="revolute">
    <origin
      xyz="0 0.16219 -0.016"
      rpy="3.1416 0 3.1416" />
    <parent
      link="link_6" />
    <child
      link="EF" />
    <axis
      xyz="0 1 0" />
    <limit
      lower="-3.1416"
      upper="3.1416"
      effort="0"
      velocity="0" />
  </joint>
</robot>